Workbook

Sheet SEC. GOBIERNO
A1: AVANCE PLAN DE DESARROLLO JUNTOS CONSTRUIMOS 2024 -2027 01. JUNTOS POR LA GOBERNANZA, LA SEGURIDAD, LA MOVILIDAD Y LA HUMANIZACIÓN DE LA SALUD
A2: COMPONENTE | B2: PROGRAMA | C2: CÓDIGO DE PRODUCTO | D2: INDICADOR DE PRODUCTO | E2: UNIDAD DE MEDIDA | F2: TENDENCIA | G2: LINEA BASE | H2: META CUATRENIO | I2: META 2024 | J2: AVANCE META 2024 | K2: % CUMPLIMIENTO P.A 2024 | L2: % AVANCE P.D. 2024 | M2: META 2025 | N2: AVANCE META 2025 | O2: % CUMPLIMIENTO P.A 2025 | P2: % AVANCE P.D. 2025 | Q2: META 2026 | R2: AVANCE META 2026 | S2: % CUMPLIMIENTO P.A 2026 | T2: % AVANCE P.D. 2026 | U2: META 2027 | V2: AVANCE META 2027 | W2: % CUMPLIMIENTO P.A 2027 | X2: % AVANCE P.D. 2027 | Y2: AVANCE ACUMULADO META 2024 Y 2025 | Z2: % AVANCE A LA FECHA P.D. | AA2: AVANCE PLAN DE DESARROLLO HASTA LA FECHA
A3: 010101 Implementación de un plan integral de seguridad y convivencia ciudadana | B3: 010101 Implementación de un plan integral de seguridad y convivencia ciudadana | C3: 450104800 | D3: Estrategias implementadas | E3: Número | F3: Incremento | G3: 0 | H3: 1 | I3: 0.25 | J3: 0.25 | K3: =IF((J3/I3)>1,1,J3/I3) -> 1 | L3: =IF((J3/H3)>1,1,J3/H3) -> 0.25 | M3: 0.25 | N3: 0.25 | O3: =IF((N3/M3)>1,1,N3/M3) -> 1 | P3: =IF((N3/H3)>1,1,N3/H3) -> 0.25 | Q3: 0.25 | R3: 0 | S3: =IF((R3/Q3)>1,1,R3/Q3) -> 0 | T3: =IF((R3/H3)>1,1,R3/H3) -> 0 | U3: 0.25 | V3: 0 | W3: =IF((V3/U3)>1,1,V3/U3) -> 0 | X3: =IF((V3/H3)>1,1,V3/H3) -> 0 | Y3: =+J3+N3+R3+V3 -> 0.5 | Z3: =IF((Y3/H3)>1,1,Y3/H3) -> 0.5 | AA3: LÍNEA ESTRATÉGICA | AB3: NUMERO DE PROGRAMAS | AC3: % AVANCE A LA FECHA P.D.
B4: 010102 Fortalecimiento del Centro de monitoreo y control | C4: 450102800 | D4: Cámaras de seguridad instaladas | E4: Número | F4: Incremento | G4: 0 | H4: 10 | I4: 1 | J4: 8 | K4: =IF((J4/I4)>1,1,J4/I4) -> 1 | L4: =IF((J4/H4)>1,1,J4/H4) -> 0.8 | M4: 3 | N4: 13 | O4: =IF((N4/M4)>1,1,N4/M4) -> 1 | P4: =IF((N4/H4)>1,1,N4/H4) -> 1 | Q4: 3 | R4: 0 | S4: =IF((R4/Q4)>1,1,R4/Q4) -> 0 | T4: =IF((R4/H4)>1,1,R4/H4) -> 0 | U4: 3 | V4: 0 | W4: =IF((V4/U4)>1,1,V4/U4) -> 0 | X4: =IF((V4/H4)>1,1,V4/H4) -> 0 | Y4: =+J4+N4+R4+V4 -> 21 | Z4: =IF((Y4/H4)>1,1,Y4/H4) -> 1 | AA4: 01. JUNTOS POR LA GOBERNANZA, LA SEGURIDAD, LA MOVILIDAD Y LA HUMANIZACIÓN DE LA SALUD | AB4: 25 | AC4: =Z28 -> 0.45652857
B5: 010103 Implementación de estrategias de prevención y control para navegabilidad en el embalse Peñol - Guatapé | C5: 450102600 | D5: Planes estratégicos elaborados | E5: Número | F5: Incremento | G5: 0 | H5: 1 | I5: 0.25 | J5: 0.15 | K5: =IF((J5/I5)>1,1,J5/I5) -> 0.6 | L5: =IF((J5/H5)>1,1,J5/H5) -> 0.15 | M5: 0.25 | N5: 0.25 | O5: =IF((N5/M5)>1,1,N5/M5) -> 1 | P5: =IF((N5/H5)>1,1,N5/H5) -> 0.25 | Q5: 0.25 | R5: 0 | S5: =IF((R5/Q5)>1,1,R5/Q5) -> 0 | T5: =IF((R5/H5)>1,1,R5/H5) -> 0 | U5: 0.25 | V5: 0 | W5: =IF((V5/U5)>1,1,V5/U5) -> 0 | X5: =IF((V5/H5)>1,1,V5/H5) -> 0 | Y5: =+J5+N5+R5+V5 -> 0.4 | Z5: =IF((Y5/H5)>1,1,Y5/H5) -> 0.4
A6: 010102 Fortalecimiento del Centro de monitoreo y control | B6: 010201 Actualización e Implementación del Plan de movilidad Municipal | C6: 450102600 | D6: Planes estratégicos elaborados | E6: Número | F6: Incremento | G6: 0 | H6: 1 | I6: 0.25 | J6: 0.2 | K6: =IF((J6/I6)>1,1,J6/I6) -> 0.8 | L6: =IF((J6/H6)>1,1,J6/H6) -> 0.2 | M6: 0.25 | N6: 0.1 | O6: =IF((N6/M6)>1,1,N6/M6) -> 0.4 | P6: =IF((N6/H6)>1,1,N6/H6) -> 0.1 | Q6: 0.25 | R6: 0 | S6: =IF((R6/Q6)>1,1,R6/Q6) -> 0 | T6: =IF((R6/H6)>1,1,R6/H6) -> 0 | U6: 0.25 | V6: 0 | W6: =IF((V6/U6)>1,1,V6/U6) -> 0 | X6: =IF((V6/H6)>1,1,V6/H6) -> 0 | Y6: =+J6+N6+R6+V6 -> 0.3 | Z6: =IF((Y6/H6)>1,1,Y6/H6) -> 0.3
B7: 010202 Gestión para la pavimentación de vías para la integración regional | C7: 240204112 | D7: Vía terciaria pavimentada | E7: Kilómetros | F7: Incremento | G7: 0 | H7: 4 | I7: 1 | J7: 0 | K7: =IF((J7/I7)>1,1,J7/I7) -> 0 | L7: =IF((J7/H7)>1,1,J7/H7) -> 0 | M7: 1 | N7: 0.81 | O7: =IF((N7/M7)>1,1,N7/M7) -> 0.81 | P7: =IF((N7/H7)>1,1,N7/H7) -> 0.2025 | Q7: 1 | R7: 0 | S7: =IF((R7/Q7)>1,1,R7/Q7) -> 0 | T7: =IF((R7/H7)>1,1,R7/H7) -> 0 | U7: 1 | V7: 0 | W7: =IF((V7/U7)>1,1,V7/U7) -> 0 | X7: =IF((V7/H7)>1,1,V7/H7) -> 0 | Y7: =+J7+N7+R7+V7 -> 0.81 | Z7: =IF((Y7/H7)>1,1,Y7/H7) -> 0.2025
B8: 010203 Formulación y ejecución del programa de educación y seguridad vial | C8: 240900900 | D8: Estrategias implementadas | E8: Número | F8: Incremento | G8: 0 | H8: 1 | I8: 0.25 | J8: 0.25 | K8: =IF((J8/I8)>1,1,J8/I8) -> 1 | L8: =IF((J8/H8)>1,1,J8/H8) -> 0.25 | M8: 0.25 | N8: 0.25 | O8: =IF((N8/M8)>1,1,N8/M8) -> 1 | P8: =IF((N8/H8)>1,1,N8/H8) -> 0.25 | Q8: 0.25 | R8: 0 | S8: =IF((R8/Q8)>1,1,R8/Q8) -> 0 | T8: =IF((R8/H8)>1,1,R8/H8) -> 0 | U8: 0.25 | V8: 0 | W8: =IF((V8/U8)>1,1,V8/U8) -> 0 | X8: =IF((V8/H8)>1,1,V8/H8) -> 0 | Y8: =+J8+N8+R8+V8 -> 0.5 | Z8: =IF((Y8/H8)>1,1,Y8/H8) -> 0.5
B9: 010204 Implementación de zonas de estacionamiento regulado | C9: 240906200 | D9: Celdas de estacionamiento regulado disponibles | E9: Número | F9: Incremento | G9: 0 | H9: 10 | I9: 0 | J9: 0 | L9: =IF((J9/H9)>1,1,J9/H9) -> 0 | M9: 5 | N9: 0 | O9: =IF((N9/M9)>1,1,N9/M9) -> 0 | P9: =IF((N9/H9)>1,1,N9/H9) -> 0 | Q9: 5 | R9: 0 | S9: =IF((R9/Q9)>1,1,R9/Q9) -> 0 | T9: =IF((R9/H9)>1,1,R9/H9) -> 0 | U9: 0 | V9: 0 | X9: =IF((V9/H9)>1,1,V9/H9) -> 0 | Y9: =+J9+N9+R9+V9 -> 0 | Z9: =IF((Y9/H9)>1,1,Y9/H9) -> 0
A10: 010103 Implementación de estrategias de prevención y control para navegabilidad en el embalse Peñol - Guatapé | B10: 010301 Formulación, ejecución, seguimiento, evaluación y control del plan de desarrollo municipal | C10: 459901900 | D10: Documentos de planeación realizados | E10: Número | F10: Incremento | G10: 0 | H10: 1 | I10: 0.4 | J10: 0.4 | K10: =IF((J10/I10)>1,1,J10/I10) -> 1 | L10: =IF((J10/H10)>1,1,J10/H10) -> 0.4 | M10: 0.2 | N10: 0.2 | O10: =IF((N10/M10)>1,1,N10/M10) -> 1 | P10: =IF((N10/H10)>1,1,N10/H10) -> 0.2 | Q10: 0.2 | R10: 0 | S10: =IF((R10/Q10)>1,1,R10/Q10) -> 0 | T10: =IF((R10/H10)>1,1,R10/H10) -> 0 | U10: 0.2 | V10: 0 | W10: =IF((V10/U10)>1,1,V10/U10) -> 0 | X10: =IF((V10/H10)>1,1,V10/H10) -> 0 | Y10: =+J10+N10+R10+V10 -> 0.6 | Z10: =IF((Y10/H10)>1,1,Y10/H10) -> 0.6
B11: 010302 Fortalecimiento del modelo integrado de planeación y gestión (MIPG), acorde con los lineamientos del decreto 1499 -2017 | C11: 459902304 | D11: Herramientas implementadas | E11: Número | F11: Incremento | G11: 0 | H11: 7 | I11: 2 | J11: 0 | K11: =IF((J11/I11)>1,1,J11/I11) -> 0 | L11: =IF((J11/H11)>1,1,J11/H11) -> 0 | M11: 2 | N11: 2 | O11: =IF((N11/M11)>1,1,N11/M11) -> 1 | P11: =IF((N11/H11)>1,1,N11/H11) -> 0.28571429 | Q11: 2 | R11: 0 | S11: =IF((R11/Q11)>1,1,R11/Q11) -> 0 | T11: =IF((R11/H11)>1,1,R11/H11) -> 0 | U11: 1 | V11: 0 | W11: =IF((V11/U11)>1,1,V11/U11) -> 0 | X11: =IF((V11/H11)>1,1,V11/H11) -> 0 | Y11: =+J11+N11+R11+V11 -> 2 | Z11: =IF((Y11/H11)>1,1,Y11/H11) -> 0.28571429
B12: 010303 Elaboración de procesos integrales de evaluación institucional y reorganización administrativa | C12: 459900100 | D12: Documentos de evaluación elaborados | E12: Número | F12: Incremento | G12: 0 | H12: 5 | I12: 0 | J12: 0 | L12: =IF((J12/H12)>1,1,J12/H12) -> 0 | M12: 2 | N12: 0 | O12: =IF((N12/M12)>1,1,N12/M12) -> 0 | P12: =IF((N12/H12)>1,1,N12/H12) -> 0 | Q12: 2 | R12: 0 | S12: =IF((R12/Q12)>1,1,R12/Q12) -> 0 | T12: =IF((R12/H12)>1,1,R12/H12) -> 0 | U12: 1 | V12: 0 | W12: =IF((V12/U12)>1,1,V12/U12) -> 0 | X12: =IF((V12/H12)>1,1,V12/H12) -> 0 | Y12: =+J12+N12+R12+V12 -> 0 | Z12: =IF((Y12/H12)>1,1,Y12/H12) -> 0
B13: 010304 Diseño e implementación de Programas de capacitación y asistencia técnica. | C13: 360401301 | D13: Eventos de formación realizados | E13: Número | F13: Incremento | G13: 0 | H13: 19 | I13: 4 | J13: 19 | K13: =IF((J13/I13)>1,1,J13/I13) -> 1 | L13: =IF((J13/H13)>1,1,J13/H13) -> 1 | M13: 5 | N13: 5 | O13: =IF((N13/M13)>1,1,N13/M13) -> 1 | P13: =IF((N13/H13)>1,1,N13/H13) -> 0.26315789 | Q13: 5 | R13: 0 | S13: =IF((R13/Q13)>1,1,R13/Q13) -> 0 | T13: =IF((R13/H13)>1,1,R13/H13) -> 0 | U13: 5 | V13: 0 | W13: =IF((V13/U13)>1,1,V13/U13) -> 0 | X13: =IF((V13/H13)>1,1,V13/H13) -> 0 | Y13: =+J13+N13+R13+V13 -> 24 | Z13: =IF((Y13/H13)>1,1,Y13/H13) -> 1
B14: 010305 Fortalecimiento de los procesos de gestión documental acorde a la normatividad legal aplicable | C14: 459901700 | D14: Sistema de gestión documental implementado | E14: Número | F14: Incremento | G14: 0 | H14: 1 | I14: 0.25 | J14: 0.2 | K14: =IF((J14/I14)>1,1,J14/I14) -> 0.8 | L14: =IF((J14/H14)>1,1,J14/H14) -> 0.2 | M14: 0.25 | N14: 0.25 | O14: =IF((N14/M14)>1,1,N14/M14) -> 1 | P14: =IF((N14/H14)>1,1,N14/H14) -> 0.25 | Q14: 0.25 | R14: 0 | S14: =IF((R14/Q14)>1,1,R14/Q14) -> 0 | T14: =IF((R14/H14)>1,1,R14/H14) -> 0 | U14: 0.25 | V14: 0 | W14: =IF((V14/U14)>1,1,V14/U14) -> 0 | X14: =IF((V14/H14)>1,1,V14/H14) -> 0 | Y14: =+J14+N14+R14+V14 -> 0.45 | Z14: =IF((Y14/H14)>1,1,Y14/H14) -> 0.45
B15: 010306 Fortalecimiento de los Sistemas de Información y Comunicación de la entidad | C15: 450100700 | D15: Sistemas de información implementados | E15: Número | F15: Incremento | G15: 0 | H15: 1 | I15: 0.25 | J15: 0.25 | K15: =IF((J15/I15)>1,1,J15/I15) -> 1 | L15: =IF((J15/H15)>1,1,J15/H15) -> 0.25 | M15: 0.25 | N15: 0.25 | O15: =IF((N15/M15)>1,1,N15/M15) -> 1 | P15: =IF((N15/H15)>1,1,N15/H15) -> 0.25 | Q15: 0.25 | R15: 0 | S15: =IF((R15/Q15)>1,1,R15/Q15) -> 0 | T15: =IF((R15/H15)>1,1,R15/H15) -> 0 | U15: 0.25 | V15: 0 | W15: =IF((V15/U15)>1,1,V15/U15) -> 0 | X15: =IF((V15/H15)>1,1,V15/H15) -> 0 | Y15: =+J15+N15+R15+V15 -> 0.5 | Z15: =IF((Y15/H15)>1,1,Y15/H15) -> 0.5
B16: 010307 Fortalecimiento de la hacienda pública y fiscalización | C16: 459900200 | D16: Programa de sanemiento fiscal y financiero ejecutado | E16: Porcentaje | F16: Incremento | G16: 0 | H16: 1 | I16: 0.25 | J16: 0.1 | K16: =IF((J16/I16)>1,1,J16/I16) -> 0.4 | L16: =IF((J16/H16)>1,1,J16/H16) -> 0.1 | M16: 0.25 | N16: 0.25 | O16: =IF((N16/M16)>1,1,N16/M16) -> 1 | P16: =IF((N16/H16)>1,1,N16/H16) -> 0.25 | Q16: 0.25 | R16: 0 | S16: =IF((R16/Q16)>1,1,R16/Q16) -> 0 | T16: =IF((R16/H16)>1,1,R16/H16) -> 0 | U16: 0.25 | V16: 0 | W16: =IF((V16/U16)>1,1,V16/U16) -> 0 | X16: =IF((V16/H16)>1,1,V16/H16) -> 0 | Y16: =+J16+N16+R16+V16 -> 0.35 | Z16: =IF((Y16/H16)>1,1,Y16/H16) -> 0.35
B17: 010308 Revisión y ajuste del esquema de ordenamiento territorial EOT | C17: 459901900 | D17: Documentos de planeación realizados | E17: Número | F17: Incremento | G17: 0 | H17: 1 | I17: 0 | J17: 0 | L17: =IF((J17/H17)>1,1,J17/H17) -> 0 | M17: 1 | N17: 0.1 | O17: =IF((N17/M17)>1,1,N17/M17) -> 0.1 | P17: 0 | Q17: 0 | R17: 0 | T17: =IF((R17/H17)>1,1,R17/H17) -> 0 | U17: 0 | V17: 0 | X17: =IF((V17/H17)>1,1,V17/H17) -> 0 | Y17: =+J17+N17+R17+V17 -> 0.1 | Z17: =IF((Y17/H17)>1,1,Y17/H17) -> 0.1
B18: 010309 Gestión de instrumentos de financiación del esquema de ordenamiento territorial EOT | C18: 459901900 | D18: Documentos de planeación realizados | E18: Número | F18: Incremento | G18: 0 | H18: 2 | I18: 0 | J18: 0 | L18: =IF((J18/H18)>1,1,J18/H18) -> 0 | M18: 0 | N18: 0.1 | P18: 0 | Q18: 1 | R18: 0 | S18: =IF((R18/Q18)>1,1,R18/Q18) -> 0 | T18: =IF((R18/H18)>1,1,R18/H18) -> 0 | U18: 1 | V18: 0 | W18: =IF((V18/U18)>1,1,V18/U18) -> 0 | X18: =IF((V18/H18)>1,1,V18/H18) -> 0 | Y18: =+J18+N18+R18+V18 -> 0.1 | Z18: =IF((Y18/H18)>1,1,Y18/H18) -> 0.05
B19: 010310 Fortalecimiento de la capacidad institucional a través de la dotación integral | C19: 450108300 | D19: Infraestructura de soporte adecuada | E19: Número | F19: Incremento | G19: 0 | H19: 1 | I19: 0 | J19: 0.3 | L19: =IF((J19/H19)>1,1,J19/H19) -> 0.3 | M19: 1 | N19: 0.7 | O19: =IF((N19/M19)>1,1,N19/M19) -> 0.7 | P19: =IF((N19/H19)>1,1,N19/H19) -> 0.7 | Q19: 0 | R19: 0 | T19: =IF((R19/H19)>1,1,R19/H19) -> 0 | U19: 0 | V19: 0 | X19: =IF((V19/H19)>1,1,V19/H19) -> 0 | Y19: =+J19+N19+R19+V19 -> 1 | Z19: =IF((Y19/H19)>1,1,Y19/H19) -> 1
B20: 010311 Generación de Alianzas con actores tanto públicos como privados para continuar potenciando los recursos municipales y mejorando las condiciones económicas del territorio y sus habitantes | C20: 459903104 | D20: Proyectos asistidos técnicamente | E20: Número | F20: Incremento | G20: 0 | H20: 4 | I20: 1 | J20: 1 | K20: =IF((J20/I20)>1,1,J20/I20) -> 1 | L20: =IF((J20/H20)>1,1,J20/H20) -> 0.25 | M20: 1 | N20: 1 | O20: =IF((N20/M20)>1,1,N20/M20) -> 1 | P20: =IF((N20/H20)>1,1,N20/H20) -> 0.25 | Q20: 1 | R20: 0 | S20: =IF((R20/Q20)>1,1,R20/Q20) -> 0 | T20: =IF((R20/H20)>1,1,R20/H20) -> 0 | U20: 1 | V20: 0 | W20: =IF((V20/U20)>1,1,V20/U20) -> 0 | X20: =IF((V20/H20)>1,1,V20/H20) -> 0 | Y20: =+J20+N20+R20+V20 -> 2 | Z20: =IF((Y20/H20)>1,1,Y20/H20) -> 0.5
B21: 010312 Fortalecimiento de la Gestión catastral | C21: 459903105 | D21: Proyectos asistidos técnicamente | E21: Número | F21: Incremento | G21: 0 | H21: 1 | I21: 0.25 | J21: 0 | K21: =IF((J21/I21)>1,1,J21/I21) -> 0 | L21: =IF((J21/H21)>1,1,J21/H21) -> 0 | M21: 0.25 | N21: 0.75 | O21: =IF((N21/M21)>1,1,N21/M21) -> 1 | P21: =IF((N21/H21)>1,1,N21/H21) -> 0.75 | Q21: 0.25 | R21: 0 | S21: =IF((R21/Q21)>1,1,R21/Q21) -> 0 | T21: =IF((R21/H21)>1,1,R21/H21) -> 0 | U21: 0.25 | V21: 0 | W21: =IF((V21/U21)>1,1,V21/U21) -> 0 | X21: =IF((V21/H21)>1,1,V21/H21) -> 0 | Y21: =+J21+N21+R21+V21 -> 0.75 | Z21: =IF((Y21/H21)>1,1,Y21/H21) -> 0.75
A22: 0104 Juntos por la humanización de la salud, el bienestar del ser humano y una atención de calidad. | B22: 010401 Implementación del plan territorial de salud en el marco del plan decenal 2022 -2031 | C22: 190501500 | D22: Documentos de planeación elaborados | E22: Número | F22: Incremento | G22: 0 | H22: 1 | I22: 0.25 | J22: 0.25 | K22: =IF((J22/I22)>1,1,J22/I22) -> 1 | L22: =IF((J22/H22)>1,1,J22/H22) -> 0.25 | M22: 0.25 | N22: 0.25 | O22: =IF((N22/M22)>1,1,N22/M22) -> 1 | P22: =IF((N22/H22)>1,1,N22/H22) -> 0.25 | Q22: 0.25 | R22: 0 | S22: =IF((R22/Q22)>1,1,R22/Q22) -> 0 | T22: =IF((R22/H22)>1,1,R22/H22) -> 0 | U22: 0.25 | V22: 0 | W22: =IF((V22/U22)>1,1,V22/U22) -> 0 | X22: =IF((V22/H22)>1,1,V22/H22) -> 0 | Y22: =+J22+N22+R22+V22 -> 0.5 | Z22: =IF((Y22/H22)>1,1,Y22/H22) -> 0.5
B23: 010402. Fortalecimiento de la Autoridad Sanitaria | C23: 190501505 | D23: Planes estratégicos elaborados | E23: Número | F23: Incremento | G23: 0 | H23: 1 | I23: 0.25 | J23: 0.25 | K23: =IF((J23/I23)>1,1,J23/I23) -> 1 | L23: =IF((J23/H23)>1,1,J23/H23) -> 0.25 | M23: 0.25 | N23: 0.25 | O23: =IF((N23/M23)>1,1,N23/M23) -> 1 | P23: =IF((N23/H23)>1,1,N23/H23) -> 0.25 | Q23: 0.25 | R23: 0 | S23: =IF((R23/Q23)>1,1,R23/Q23) -> 0 | T23: =IF((R23/H23)>1,1,R23/H23) -> 0 | U23: 0.25 | V23: 0 | W23: =IF((V23/U23)>1,1,V23/U23) -> 0 | X23: =IF((V23/H23)>1,1,V23/H23) -> 0 | Y23: =+J23+N23+R23+V23 -> 0.5 | Z23: =IF((Y23/H23)>1,1,Y23/H23) -> 0.5
B24: 010403. Fortalecimiento de la Salud Pública | C24: 190501505 | D24: Planes estratégicos elaborados | E24: Número | F24: Incremento | G24: 0 | H24: 1 | I24: 0.25 | J24: 0.18 | K24: =IF((J24/I24)>1,1,J24/I24) -> 0.72 | L24: =IF((J24/H24)>1,1,J24/H24) -> 0.18 | M24: 0.25 | N24: 0.25 | O24: =IF((N24/M24)>1,1,N24/M24) -> 1 | P24: =IF((N24/H24)>1,1,N24/H24) -> 0.25 | Q24: 0.25 | R24: 0 | S24: =IF((R24/Q24)>1,1,R24/Q24) -> 0 | T24: =IF((R24/H24)>1,1,R24/H24) -> 0 | U24: 0.25 | V24: 0 | W24: =IF((V24/U24)>1,1,V24/U24) -> 0 | X24: =IF((V24/H24)>1,1,V24/H24) -> 0 | Y24: =+J24+N24+R24+V24 -> 0.43 | Z24: =IF((Y24/H24)>1,1,Y24/H24) -> 0.43
B25: 010404. Mejoramiento de Infraestructura de Salud | C25: 190600600 | D25: Hospitales de primer nivel de atención modificados | E25: Número | F25: Incremento | G25: 0 | H25: 1 | I25: 0.25 | J25: 0.12 | K25: =IF((J25/I25)>1,1,J25/I25) -> 0.48 | L25: =IF((J25/H25)>1,1,J25/H25) -> 0.12 | M25: 0.25 | N25: 0 | O25: =IF((N25/M25)>1,1,N25/M25) -> 0 | P25: =IF((N25/H25)>1,1,N25/H25) -> 0 | Q25: 0.25 | R25: 0 | S25: =IF((R25/Q25)>1,1,R25/Q25) -> 0 | T25: =IF((R25/H25)>1,1,R25/H25) -> 0 | U25: 0.25 | V25: 0 | W25: =IF((V25/U25)>1,1,V25/U25) -> 0 | X25: =IF((V25/H25)>1,1,V25/H25) -> 0 | Y25: =+J25+N25+R25+V25 -> 0.12 | Z25: =IF((Y25/H25)>1,1,Y25/H25) -> 0.12
A26: 0105 Juntos por el Desarrollo Comunitario Equitativo | B26: 010501. Fomento de la participación ciudadana | C26: 450200113 | D26: Estrategias de promoción a la participación ciudadana implementadas | E26: Número | F26: Incremento | G26: 0 | H26: 4 | I26: 1 | J26: 0.5 | K26: =IF((J26/I26)>1,1,J26/I26) -> 0.5 | L26: =IF((J26/H26)>1,1,J26/H26) -> 0.125 | M26: 1 | N26: 1 | O26: =IF((N26/M26)>1,1,N26/M26) -> 1 | P26: =IF((N26/H26)>1,1,N26/H26) -> 0.25 | Q26: 1 | R26: 0 | S26: =IF((R26/Q26)>1,1,R26/Q26) -> 0 | T26: =IF((R26/H26)>1,1,R26/H26) -> 0 | U26: 1 | V26: 0 | W26: =IF((V26/U26)>1,1,V26/U26) -> 0 | X26: =IF((V26/H26)>1,1,V26/H26) -> 0 | Y26: =+J26+N26+R26+V26 -> 1.5 | Z26: =IF((Y26/H26)>1,1,Y26/H26) -> 0.375
B27: 010502 Construcción y mantenimiento de sedes comunales | C27: 450200700 | D27: Salones comunales construidos | E27: Número | F27: Incremento | G27: 0 | H27: 2 | I27: 0 | J27: 0 | L27: =IF((J27/H27)>1,1,J27/H27) -> 0 | M27: 2 | N27: 2 | O27: =IF((N27/M27)>1,1,N27/M27) -> 1 | P27: =IF((N27/H27)>1,1,N27/H27) -> 1 | Q27: 0 | R27: 0 | T27: =IF((R27/H27)>1,1,R27/H27) -> 0 | U27: 0 | V27: 0 | X27: =IF((V27/H27)>1,1,V27/H27) -> 0 | Y27: =+J27+N27+R27+V27 -> 2 | Z27: =IF((Y27/H27)>1,1,Y27/H27) -> 1
J28: TOTAL 2024 | K28: =AVERAGE(K3:K27) -> 0.7 | L28: =AVERAGE(L3:L27) -> 0.203 | N28: TOTAL 2025 | O28: =AVERAGE(O3:O27) -> 0.79208333 | P28: =AVERAGE(P3:P27) -> 0.29005489 | R28: TOTAL 2026 | S28: =AVERAGE(S3:S27) -> 0 | T28: =AVERAGE(T3:T27) -> 0 | V28: TOTAL 2026 | W28: =AVERAGE(W3:W27) -> 0 | X28: =AVERAGE(X3:X27) -> 0 | Y28: TOTAL ACUMULADO | Z28: =AVERAGE(Z3:Z27) -> 0.45652857

Sheet SEC. BIENESTAR Y DLLO SOCIAL
A1: AVANCE PLAN DE DESARROLLO JUNTOS CONSTRUIMOS 2024 -2027 LINEA ESTRATÉGICA: 02. JUNTOS POR EL MOVIMIENTO NIÑO: EQUIDAD SOCIAL, EDUCACIÓN, CULTURA Y DEPORTE
A2: LÍNEA ESTRATÉGICA | B2: COMPONENTE | C2: PROGRAMA | D2: CÓDIGO DE PRODUCTO | E2: INDICADOR DE PRODUCTO | F2: UNIDAD DE MEDIDA | G2: TENDENCIA | H2: LINEA BASE | I2: META CUATRENIO | J2: META 2024 | K2: AVANCE META 2024 | L2: % CUMPLIMIENTO P.A 2024 | M2: % AVANCE P.D. 2024 | N2: META 2025 | O2: AVANCE META 2025 | P2: % CUMPLIMIENTO P.A 2025 | Q2: % AVANCE P.D. 2025 | R2: META 2026 | S2: AVANCE META 2026 | T2: % CUMPLIMIENTO P.A 2026 | U2: % AVANCE P.D. 2026 | V2: META 2027 | W2: AVANCE META 2027 | X2: % CUMPLIMIENTO P.A 2026 | Y2: % AVANCE P.D. 2026 | Z2: AVANCE ACUMULADO META 2024 Y 2025 | AA2: % AVANCE A LA FECHA P.D. | AB2: AVANCE PLAN DE DESARROLLO HASTA LA FECHA
A3: LINEA ESTRATÉGICA: 02. JUNTOS POR EL MOVIMIENTO NIÑO: EQUIDAD SOCIAL, EDUCACIÓN, CULTURA Y DEPORTE | B3: 0201 Juntos por la Educación con pertinencia, vocación para el desarrollo y reducción de la desigualdad. | C3: 020101 Fortalecimiento del PAE (Programa de Alimentación Escolar) en términos de cobertura y calidad | D3: 220102805 | E3: Estudiantes beneficiados del programa de alimentación escolar | F3: Número | G3: Mantenimiento | H3: 884 | I3: 884 | J3: 884 | K3: 884 | L3: =IF((K3/J3)>1,1,K3/J3) -> 1 | M3: =IF((K3/I3)>1,1,K3/I3) -> 1 | N3: 884 | O3: 919 | P3: =IF((O3/N3)>1,1,O3/N3) -> 1 | Q3: =IF((O3/I3)>1,1,O3/I3) -> 1 | R3: 884 | S3: 0 | T3: =IF((S3/R3)>1,1,S3/R3) -> 0 | U3: =IF((S3/I3)>1,1,S3/I3) -> 0 | V3: 884 | W3: 0 | X3: =IF((W3/V3)>1,1,W3/V3) -> 0 | Y3: =IF((W3/I3)>1,1,W3/I3) -> 0 | Z3: =+O3 -> 919 | AA3: =IF((Z3/I3)>1,1,Z3/I3) -> 1 | AB3: LÍNEA ESTRATÉGICA | AC3: NUMERO DE PROGRAMAS | AD3: % AVANCE A LA FECHA P.D.
C4: 020102 Mejoramiento del programa de transporte escolar municipal en términos de permanencia | D4: 220102901 | E4: Días de atención del servicio de transporte escolar | F4: Número | G4: Incremento | H4: 168 | I4: 180 | J4: 171 | K4: 176 | L4: =IF((K4/J4)>1,1,K4/J4) -> 1 | M4: =IF((K4/I4)>1,1,K4/I4) -> 0.97777778 | N4: 174 | O4: 192 | P4: =IF((O4/N4)>1,1,O4/N4) -> 1 | Q4: =IF((O4/I4)>1,1,O4/I4) -> 1 | R4: 177 | S4: 0 | T4: =IF((S4/R4)>1,1,S4/R4) -> 0 | U4: =IF((S4/I4)>1,1,S4/I4) -> 0 | V4: 180 | W4: 0 | X4: =IF((W4/V4)>1,1,W4/V4) -> 0 | Y4: =IF((W4/I4)>1,1,W4/I4) -> 0 | Z4: =+O4 -> 192 | AA4: =IF((Z4/I4)>1,1,Z4/I4) -> 1 | AB4: 02. JUNTOS POR EL MOVIMIENTO NIÑO: EQUIDAD SOCIAL, EDUCACIÓN, CULTURA Y DEPORTE | AC4: 31 | AD4: =AA34 -> 0.54032963
C5: 020103 Fortalecimiento de cobertura y calidad educativa para la resignificación y complementación de la jornada escolar | D5: 220100301 | E5: Programas realizados | F5: Número | G5: Mantenimiento | H5: 1 | I5: 1 | J5: 1 | K5: 1 | L5: =IF((K5/J5)>1,1,K5/J5) -> 1 | M5: =IF((K5/I5)>1,1,K5/I5) -> 1 | N5: 1 | O5: 1 | P5: =IF((O5/N5)>1,1,O5/N5) -> 1 | Q5: =IF((O5/I5)>1,1,O5/I5) -> 1 | R5: 1 | S5: 0 | T5: =IF((S5/R5)>1,1,S5/R5) -> 0 | U5: =IF((S5/I5)>1,1,S5/I5) -> 0 | V5: 1 | W5: 0 | X5: =IF((W5/V5)>1,1,W5/V5) -> 0 | Y5: =IF((W5/I5)>1,1,W5/I5) -> 0 | Z5: =+O5 -> 1 | AA5: =IF((Z5/I5)>1,1,Z5/I5) -> 1
C6: 20104 Fortalecimiento de los programas y proyectos de bibliotecas | D6: 330108500 | E6: Usuarios atendidos | F6: Número | G6: Incremento | H6: 0 | I6: 25600 | J6: 6400 | K6: 6566 | L6: =IF((K6/J6)>1,1,K6/J6) -> 1 | M6: =IF((K6/I6)>1,1,K6/I6) -> 0.25648437 | N6: 6400 | O6: 6836 | P6: =IF((O6/N6)>1,1,O6/N6) -> 1 | Q6: =IF((O6/I6)>1,1,O6/I6) -> 0.26703125 | R6: 6400 | S6: 0 | T6: =IF((S6/R6)>1,1,S6/R6) -> 0 | U6: =IF((S6/I6)>1,1,S6/I6) -> 0 | V6: 6400 | W6: 0 | X6: =IF((W6/V6)>1,1,W6/V6) -> 0 | Y6: =IF((W6/I6)>1,1,W6/I6) -> 0 | Z6: =+K6+O6+S6+W6 -> 13402 | AA6: =IF((Z6/I6)>1,1,Z6/I6) -> 0.52351563
C7: 20105 Fortalecimiento del acceso a la Educación Superior “Guatapé. vive la U” | D7: 220206200 | E7: Beneficiarios de estrategias o programas de fomento para el acceso a la educación superior | F7: Número | G7: Incremento | H7: 0 | I7: 800 | J7: 200 | K7: 478 | L7: =IF((K7/J7)>1,1,K7/J7) -> 1 | M7: =IF((K7/I7)>1,1,K7/I7) -> 0.5975 | N7: 200 | O7: 200 | P7: =IF((O7/N7)>1,1,O7/N7) -> 1 | Q7: =IF((O7/I7)>1,1,O7/I7) -> 0.25 | R7: 200 | S7: 0 | T7: =IF((S7/R7)>1,1,S7/R7) -> 0 | U7: =IF((S7/I7)>1,1,S7/I7) -> 0 | V7: 200 | W7: 0 | X7: =IF((W7/V7)>1,1,W7/V7) -> 0 | Y7: =IF((W7/I7)>1,1,W7/I7) -> 0 | Z7: =+K7+O7+S7+W7 -> 678 | AA7: =IF((Z7/I7)>1,1,Z7/I7) -> 0.8475
C8: 20106 Mejoramiento de la infraestructura de sedes educativas | D8: 220105200 | E8: Sedes educativas mejoradas | F8: Número | G8: Incremento | H8: 0 | I8: 8 | J8: 2 | K8: 1 | L8: =IF((K8/J8)>1,1,K8/J8) -> 0.5 | M8: =IF((K8/I8)>1,1,K8/I8) -> 0.125 | N8: 2 | O8: 2 | P8: =IF((O8/N8)>1,1,O8/N8) -> 1 | Q8: =IF((O8/I8)>1,1,O8/I8) -> 0.25 | R8: 2 | S8: 0 | T8: =IF((S8/R8)>1,1,S8/R8) -> 0 | U8: =IF((S8/I8)>1,1,S8/I8) -> 0 | V8: 2 | W8: 0 | X8: =IF((W8/V8)>1,1,W8/V8) -> 0 | Y8: =IF((W8/I8)>1,1,W8/I8) -> 0 | Z8: =+K8+O8+S8+W8 -> 3 | AA8: =IF((Z8/I8)>1,1,Z8/I8) -> 0.375
C9: 20107 Fortalecimiento de ambientes de aprendizaje para la ciencia. tecnologia. la innovacion y la formacion para la vida | D9: 220102600 | E9: Ambientes de aprendizaje en funcionamiento | F9: Número | G9: Incremento | H9: 0 | I9: 2 | J9: 0.5 | K9: 0.5 | L9: =IF((K9/J9)>1,1,K9/J9) -> 1 | M9: =IF((K9/I9)>1,1,K9/I9) -> 0.25 | N9: 0.5 | O9: 0.5 | P9: =IF((O9/N9)>1,1,O9/N9) -> 1 | Q9: =IF((O9/I9)>1,1,O9/I9) -> 0.25 | R9: 0.5 | S9: 0 | T9: =IF((S9/R9)>1,1,S9/R9) -> 0 | U9: =IF((S9/I9)>1,1,S9/I9) -> 0 | V9: 0.5 | W9: 0 | X9: =IF((W9/V9)>1,1,W9/V9) -> 0 | Y9: =IF((W9/I9)>1,1,W9/I9) -> 0 | Z9: =+K9+O9+S9+W9 -> 1 | AA9: =IF((Z9/I9)>1,1,Z9/I9) -> 0.5
B10: 0202 Juntos por la Cultura, Identidad y el patrimonio Guatapense | C10: 20201 Gestion para la Construcción del centro cultural y artístico del municipio de Guatapé | D10: 330106301 | E10: Viabilizaciones realizadas | F10: Número | G10: Incremento | H10: 0 | I10: 1 | J10: 0 | K10: 0.3 | M10: =IF((K10/I10)>1,1,K10/I10) -> 0.3 | N10: 0 | O10: 0 | R10: 0.5 | S10: 0 | T10: =IF((S10/R10)>1,1,S10/R10) -> 0 | U10: =IF((S10/I10)>1,1,S10/I10) -> 0 | V10: 0.5 | W10: 0 | X10: =IF((W10/V10)>1,1,W10/V10) -> 0 | Y10: =IF((W10/I10)>1,1,W10/I10) -> 0 | Z10: =+K10+O10+S10+W10 -> 0.3 | AA10: =IF((Z10/I10)>1,1,Z10/I10) -> 0.3
C11: 20202 Fortalecimiento de la cobertura de los programas del Centro de Formación Artística en la zona urbana y rural | D11: 330105100 | E11: Personas capacitadas | F11: Número | G11: Incremento | H11: 0 | I11: 8220 | J11: 2055 | K11: 2514 | L11: =IF((K11/J11)>1,1,K11/J11) -> 1 | M11: =IF((K11/I11)>1,1,K11/I11) -> 0.30583942 | N11: 2055 | O11: 2055 | P11: =IF((O11/N11)>1,1,O11/N11) -> 1 | Q11: =IF((O11/I11)>1,1,O11/I11) -> 0.25 | R11: 2055 | S11: 0 | T11: =IF((S11/R11)>1,1,S11/R11) -> 0 | U11: =IF((S11/I11)>1,1,S11/I11) -> 0 | V11: 2055 | W11: 0 | X11: =IF((W11/V11)>1,1,W11/V11) -> 0 | Y11: =IF((W11/I11)>1,1,W11/I11) -> 0 | Z11: =+K11+O11+S11+W11 -> 4569 | AA11: =IF((Z11/I11)>1,1,Z11/I11) -> 0.55583942
C12: 20203 Mantenimiento, protección y recuperación del patrimonio histórico y cultural | D12: 330202201 | E12: Planes de manejo ejecutados | F12: Número | G12: Incremento | H12: 0 | I12: 4 | J12: 1 | K12: 0 | L12: =IF((K12/J12)>1,1,K12/J12) -> 0 | M12: =IF((K12/I12)>1,1,K12/I12) -> 0 | N12: 1 | O12: 1 | P12: =IF((O12/N12)>1,1,O12/N12) -> 1 | Q12: =IF((O12/I12)>1,1,O12/I12) -> 0.25 | R12: 1 | S12: 0 | T12: =IF((S12/R12)>1,1,S12/R12) -> 0 | U12: =IF((S12/I12)>1,1,S12/I12) -> 0 | V12: 1 | W12: 0 | X12: =IF((W12/V12)>1,1,W12/V12) -> 0 | Y12: =IF((W12/I12)>1,1,W12/I12) -> 0 | Z12: =+K12+O12+S12+W12 -> 1 | AA12: =IF((Z12/I12)>1,1,Z12/I12) -> 0.25
C13: 20204 Mejoramiento de la infraestructura cultural y artística | D13: 330106800 | E13: Infraestructura cultural intervenida | F13: Número | G13: Incremento | H13: 0 | I13: 2 | J13: 1 | K13: 1 | L13: =IF((K13/J13)>1,1,K13/J13) -> 1 | M13: =IF((K13/I13)>1,1,K13/I13) -> 0.5 | N13: 1 | O13: 1 | P13: =IF((O13/N13)>1,1,O13/N13) -> 1 | Q13: =IF((O13/I13)>1,1,O13/I13) -> 0.5 | R13: 0 | S13: 0 | U13: =IF((S13/I13)>1,1,S13/I13) -> 0 | V13: 0 | W13: 0 | Y13: =IF((W13/I13)>1,1,W13/I13) -> 0 | Z13: =+K13+O13+S13+W13 -> 2 | AA13: =IF((Z13/I13)>1,1,Z13/I13) -> 1
C14: 20205 Fortalecimiento de eventos e intercambios para el fomento de expresiones artísticas y culturales | D14: 330105300 | E14: Eventos de promoción de actividades culturales realizados | F14: Número | G14: Incremento | H14: 0 | I14: 176 | J14: 44 | K14: 80 | L14: =IF((K14/J14)>1,1,K14/J14) -> 1 | M14: =IF((K14/I14)>1,1,K14/I14) -> 0.45454545 | N14: 44 | O14: 44 | P14: =IF((O14/N14)>1,1,O14/N14) -> 1 | Q14: =IF((O14/I14)>1,1,O14/I14) -> 0.25 | R14: 44 | S14: 0 | T14: =IF((S14/R14)>1,1,S14/R14) -> 0 | U14: =IF((S14/I14)>1,1,S14/I14) -> 0 | V14: 44 | W14: 0 | X14: =IF((W14/V14)>1,1,W14/V14) -> 0 | Y14: =IF((W14/I14)>1,1,W14/I14) -> 0 | Z14: =+K14+O14+S14+W14 -> 124 | AA14: =IF((Z14/I14)>1,1,Z14/I14) -> 0.70454545
C15: 20206 Implementación del Programa entrega de estímulos a los artistas guatapenses | D15: 330105402 | E15: Estímulos otorgados a los beneficiarios de Colombia Creativa | F15: Número | G15: Incremento | H15: 0 | I15: 44 | J15: 11 | K15: 11 | L15: =IF((K15/J15)>1,1,K15/J15) -> 1 | M15: =IF((K15/I15)>1,1,K15/I15) -> 0.25 | N15: 11 | O15: 11 | P15: =IF((O15/N15)>1,1,O15/N15) -> 1 | Q15: =IF((O15/I15)>1,1,O15/I15) -> 0.25 | R15: 11 | S15: 0 | T15: =IF((S15/R15)>1,1,S15/R15) -> 0 | U15: =IF((S15/I15)>1,1,S15/I15) -> 0 | V15: 11 | W15: 0 | X15: =IF((W15/V15)>1,1,W15/V15) -> 0 | Y15: =IF((W15/I15)>1,1,W15/I15) -> 0 | Z15: =+K15+O15+S15+W15 -> 22 | AA15: =IF((Z15/I15)>1,1,Z15/I15) -> 0.5
B16: 0203 Juntos por el Deporte, la recreación y la actividad física | C16: 20301 Fortalecimiento del programa de recreación. deporte y aprovechamiento del tiempo libre | D16: 430103703 | E16: Personas atendidas por los programas de recreación, deporte social comunitario, actividad física y aprovechamiento del tiempo libre | F16: Número | G16: Incremento | H16: 0 | I16: 44000 | J16: 11000 | K16: 5490 | L16: =IF((K16/J16)>1,1,K16/J16) -> 0.49909091 | M16: =IF((K16/I16)>1,1,K16/I16) -> 0.12477273 | N16: 11000 | O16: 11000 | P16: =IF((O16/N16)>1,1,O16/N16) -> 1 | Q16: =IF((O16/I16)>1,1,O16/I16) -> 0.25 | R16: 11000 | S16: 0 | T16: =IF((S16/R16)>1,1,S16/R16) -> 0 | U16: =IF((S16/I16)>1,1,S16/I16) -> 0 | V16: 11000 | W16: 0 | X16: =IF((W16/V16)>1,1,W16/V16) -> 0 | Y16: =IF((W16/I16)>1,1,W16/I16) -> 0 | Z16: =+K16+O16+S16+W16 -> 16490 | AA16: =IF((Z16/I16)>1,1,Z16/I16) -> 0.37477273
C17: 20302 Mantenimiento y adecuación de los escenarios deportivos y recreativos de la zona urbana y rural | D17: 430100300 | E17: Infraestructura deportiva en operación | F17: Número | G17: Incremento | H17: 0 | I17: 14 | J17: 3 | K17: 3 | L17: =IF((K17/J17)>1,1,K17/J17) -> 1 | M17: =IF((K17/I17)>1,1,K17/I17) -> 0.21428571 | N17: 4 | O17: 4 | P17: =IF((O17/N17)>1,1,O17/N17) -> 1 | Q17: =IF((O17/I17)>1,1,O17/I17) -> 0.28571429 | R17: 4 | S17: 0 | T17: =IF((S17/R17)>1,1,S17/R17) -> 0 | U17: =IF((S17/I17)>1,1,S17/I17) -> 0 | V17: 3 | W17: 0 | X17: =IF((W17/V17)>1,1,W17/V17) -> 0 | Y17: =IF((W17/I17)>1,1,W17/I17) -> 0 | Z17: =+K17+O17+S17+W17 -> 7 | AA17: =IF((Z17/I17)>1,1,Z17/I17) -> 0.5
C18: 20303 Dotación e implementación para práctica del deporte | D18: 430100102 | E18: Artículos deportivos entregados | F18: Número | G18: Incremento | H18: 0 | I18: 3000 | J18: 500 | K18: 1125 | L18: =IF((K18/J18)>1,1,K18/J18) -> 1 | M18: =IF((K18/I18)>1,1,K18/I18) -> 0.375 | N18: 1000 | O18: 1000 | P18: =IF((O18/N18)>1,1,O18/N18) -> 1 | Q18: =IF((O18/I18)>1,1,O18/I18) -> 0.33333333 | R18: 1000 | S18: 0 | T18: =IF((S18/R18)>1,1,S18/R18) -> 0 | U18: =IF((S18/I18)>1,1,S18/I18) -> 0 | V18: 500 | W18: 0 | X18: =IF((W18/V18)>1,1,W18/V18) -> 0 | Y18: =IF((W18/I18)>1,1,W18/I18) -> 0 | Z18: =+K18+O18+S18+W18 -> 2125 | AA18: =IF((Z18/I18)>1,1,Z18/I18) -> 0.70833333
C19: 20304 Formulación e implementación del Plan Decenal del Deporte | D19: 430100600 | E19: Documentos normativos realizados | F19: Número | G19: Incremento | H19: 0 | I19: 1 | J19: 0.25 | K19: 0 | L19: =IF((K19/J19)>1,1,K19/J19) -> 0 | M19: =IF((K19/I19)>1,1,K19/I19) -> 0 | N19: 0.25 | O19: 0.25 | P19: =IF((O19/N19)>1,1,O19/N19) -> 1 | Q19: =IF((O19/I19)>1,1,O19/I19) -> 0.25 | R19: 0.25 | S19: 0 | T19: =IF((S19/R19)>1,1,S19/R19) -> 0 | U19: =IF((S19/I19)>1,1,S19/I19) -> 0 | V19: 0.25 | W19: 0 | X19: =IF((W19/V19)>1,1,W19/V19) -> 0 | Y19: =IF((W19/I19)>1,1,W19/I19) -> 0 | Z19: =+K19+O19+S19+W19 -> 0.25 | AA19: =IF((Z19/I19)>1,1,Z19/I19) -> 0.25
C20: 20305 Apoyo integral a los deportistas destacados en diferentes categorías | D20: 430100100 | E20: Personas beneficiadas | F20: Número | G20: Incremento | H20: 0 | I20: 60 | J20: 15 | K20: 20 | L20: =IF((K20/J20)>1,1,K20/J20) -> 1 | M20: =IF((K20/I20)>1,1,K20/I20) -> 0.33333333 | N20: 15 | O20: 5 | P20: =IF((O20/N20)>1,1,O20/N20) -> 0.33333333 | Q20: =IF((O20/I20)>1,1,O20/I20) -> 0.083333333 | R20: 15 | S20: 0 | T20: =IF((S20/R20)>1,1,S20/R20) -> 0 | U20: =IF((S20/I20)>1,1,S20/I20) -> 0 | V20: 15 | W20: 0 | X20: =IF((W20/V20)>1,1,W20/V20) -> 0 | Y20: =IF((W20/I20)>1,1,W20/I20) -> 0 | Z20: =+K20+O20+S20+W20 -> 25 | AA20: =IF((Z20/I20)>1,1,Z20/I20) -> 0.41666667
C21: 20306 Fortalecimiento de organizaciones deportivas | D21: 430100104 | E21: Organismos deportivos apoyados | F21: Número | G21: Incremento | H21: 0 | I21: 12 | J21: 3 | K21: 3 | L21: =IF((K21/J21)>1,1,K21/J21) -> 1 | M21: =IF((K21/I21)>1,1,K21/I21) -> 0.25 | N21: 3 | O21: 3 | P21: =IF((O21/N21)>1,1,O21/N21) -> 1 | Q21: =IF((O21/I21)>1,1,O21/I21) -> 0.25 | R21: 3 | S21: 0 | T21: =IF((S21/R21)>1,1,S21/R21) -> 0 | U21: =IF((S21/I21)>1,1,S21/I21) -> 0 | V21: 3 | W21: 0 | X21: =IF((W21/V21)>1,1,W21/V21) -> 0 | Y21: =IF((W21/I21)>1,1,W21/I21) -> 0 | Z21: =+K21+O21+S21+W21 -> 6 | AA21: =IF((Z21/I21)>1,1,Z21/I21) -> 0.5
B22: 0204 Juntos por un Guatape Igualitario y con Equidad Social | C22: 20401 Desarrollo integral de primera infancia. niños. niñas adolescentes. por los derechos. el juego y la felicidad. | D22: 410205200 | E22: Niños, niñas, adolescentes y jóvenes beneficiados | F22: Número | G22: Mantenimiento | H22: 350 | I22: 350 | J22: 350 | K22: 350 | L22: =IF((K22/J22)>1,1,K22/J22) -> 1 | M22: =IF((K22/I22)>1,1,K22/I22) -> 1 | N22: 350 | O22: 350 | P22: =IF((O22/N22)>1,1,O22/N22) -> 1 | Q22: =IF((O22/I22)>1,1,O22/I22) -> 1 | R22: 350 | S22: 0 | T22: =IF((S22/R22)>1,1,S22/R22) -> 0 | U22: =IF((S22/I22)>1,1,S22/I22) -> 0 | V22: 350 | W22: 0 | X22: =IF((W22/V22)>1,1,W22/V22) -> 0 | Y22: =IF((W22/I22)>1,1,W22/I22) -> 0 | Z22: =+O22 -> 350 | AA22: =IF((Z22/I22)>1,1,Z22/I22) -> 1
C23: 20402 Fortalecimiento de organizaciones que permitan mejorar la equidad social integral priorizando el enfoque en la mujer. víctimas de la violencia y demás grupos vulnerables | D23: 410204200 | E23: Acciones ejecutadas con las comunidades | F23: Número | G23: Incremento | H23: 0 | I23: 2 | J23: 0 | K23: 0 | M23: =IF((K23/I23)>1,1,K23/I23) -> 0 | N23: 1 | O23: 1 | P23: =IF((O23/N23)>1,1,O23/N23) -> 1 | Q23: =IF((O23/I23)>1,1,O23/I23) -> 0.5 | R23: 1 | S23: 0 | T23: =IF((S23/R23)>1,1,S23/R23) -> 0 | U23: =IF((S23/I23)>1,1,S23/I23) -> 0 | V23: 0 | W23: 0 | Y23: =IF((W23/I23)>1,1,W23/I23) -> 0 | Z23: =+K23+O23+S23+W23 -> 1 | AA23: =IF((Z23/I23)>1,1,Z23/I23) -> 0.5
C24: 20403 Continuidad del Plan Estratégico Territorial “Movimiento Niño: desde el vientre hasta siempre”. Teniendo como base las familias y el desarrollo social en los diferentes cursos de vida. | D24: 410203501 | E24: Documentos de lineamientos técnicos en Política y Atención Integral de niños, niñas y adolescentes realizados | F24: Número | G24: Incremento | H24: 0 | I24: 4 | J24: 1 | K24: 1 | L24: =IF((K24/J24)>1,1,K24/J24) -> 1 | M24: =IF((K24/I24)>1,1,K24/I24) -> 0.25 | N24: 1 | O24: 1 | P24: =IF((O24/N24)>1,1,O24/N24) -> 1 | Q24: =IF((O24/I24)>1,1,O24/I24) -> 0.25 | R24: 1 | S24: 0 | T24: =IF((S24/R24)>1,1,S24/R24) -> 0 | U24: =IF((S24/I24)>1,1,S24/I24) -> 0 | V24: 1 | W24: 0 | X24: =IF((W24/V24)>1,1,W24/V24) -> 0 | Y24: =IF((W24/I24)>1,1,W24/I24) -> 0 | Z24: =+K24+O24+S24+W24 -> 2 | AA24: =IF((Z24/I24)>1,1,Z24/I24) -> 0.5
C25: 20404 Implementación de la política pública de Juventud | D25: 410306701 | E25: Documentos de planeación con seguimiento realizados | F25: Número | G25: Incremento | H25: 0 | I25: 1 | J25: 0.25 | K25: 0.1 | L25: =IF((K25/J25)>1,1,K25/J25) -> 0.4 | M25: =IF((K25/I25)>1,1,K25/I25) -> 0.1 | N25: 0.25 | O25: 0.25 | P25: =IF((O25/N25)>1,1,O25/N25) -> 1 | Q25: =IF((O25/I25)>1,1,O25/I25) -> 0.25 | R25: 0.25 | S25: 0 | T25: =IF((S25/R25)>1,1,S25/R25) -> 0 | U25: =IF((S25/I25)>1,1,S25/I25) -> 0 | V25: 0.25 | W25: 0 | X25: =IF((W25/V25)>1,1,W25/V25) -> 0 | Y25: =IF((W25/I25)>1,1,W25/I25) -> 0 | Z25: =+K25+O25+S25+W25 -> 0.35 | AA25: =IF((Z25/I25)>1,1,Z25/I25) -> 0.35
C26: 20405 Atención integral al Adulto Mayor. Dignificando los años Dorados | D26: 410400800 | E26: Adultos mayores atendidos con servicios integrales | F26: Número | G26: Incremento | H26: 0 | I26: 1600 | J26: 400 | K26: 400 | L26: =IF((K26/J26)>1,1,K26/J26) -> 1 | M26: =IF((K26/I26)>1,1,K26/I26) -> 0.25 | N26: 400 | O26: 400 | P26: =IF((O26/N26)>1,1,O26/N26) -> 1 | Q26: =IF((O26/I26)>1,1,O26/I26) -> 0.25 | R26: 400 | S26: 0 | T26: =IF((S26/R26)>1,1,S26/R26) -> 0 | U26: =IF((S26/I26)>1,1,S26/I26) -> 0 | V26: 400 | W26: 0 | X26: =IF((W26/V26)>1,1,W26/V26) -> 0 | Y26: =IF((W26/I26)>1,1,W26/I26) -> 0 | Z26: =+K26+O26+S26+W26 -> 800 | AA26: =IF((Z26/I26)>1,1,Z26/I26) -> 0.5
C27: 20406 Atención integral a la población con discapacidad con inclusion total | D27: 410402000 | E27: Personas con discapacidad atendidas con servicios integrales | F27: Número | G27: Incremento | H27: 0 | I27: 120 | J27: 30 | K27: 48 | L27: =IF((K27/J27)>1,1,K27/J27) -> 1 | M27: =IF((K27/I27)>1,1,K27/I27) -> 0.4 | N27: 30 | O27: 30 | P27: =IF((O27/N27)>1,1,O27/N27) -> 1 | Q27: =IF((O27/I27)>1,1,O27/I27) -> 0.25 | R27: 30 | S27: 0 | T27: =IF((S27/R27)>1,1,S27/R27) -> 0 | U27: =IF((S27/I27)>1,1,S27/I27) -> 0 | V27: 30 | W27: 0 | X27: =IF((W27/V27)>1,1,W27/V27) -> 0 | Y27: =IF((W27/I27)>1,1,W27/I27) -> 0 | Z27: =+K27+O27+S27+W27 -> 78 | AA27: =IF((Z27/I27)>1,1,Z27/I27) -> 0.65
C28: 020407 Atención integral de las víctimas y generarando escenarios de reconciliacion y paz total | D28: 410103802 | E28: Víctimas asistidas técnicamente | F28: Número | G28: Incremento | H28: 0 | I28: 400 | J28: 100 | K28: 50 | L28: =IF((K28/J28)>1,1,K28/J28) -> 0.5 | M28: =IF((K28/I28)>1,1,K28/I28) -> 0.125 | N28: 100 | O28: 100 | P28: =IF((O28/N28)>1,1,O28/N28) -> 1 | Q28: =IF((O28/I28)>1,1,O28/I28) -> 0.25 | R28: 100 | S28: 0 | T28: =IF((S28/R28)>1,1,S28/R28) -> 0 | U28: =IF((S28/I28)>1,1,S28/I28) -> 0 | V28: 100 | W28: 0 | X28: =IF((W28/V28)>1,1,W28/V28) -> 0 | Y28: =IF((W28/I28)>1,1,W28/I28) -> 0 | Z28: =+K28+O28+S28+W28 -> 150 | AA28: =IF((Z28/I28)>1,1,Z28/I28) -> 0.375
C29: 020408 Atención integral a la mujer. Empoderando a la mujer guatapense | D29: 450203800 | E29: Estrategias de promoción de la garantía de derechos implementadas | F29: Número | G29: Incremento | H29: 0 | I29: 6000 | J29: 1500 | K29: 1587 | L29: =IF((K29/J29)>1,1,K29/J29) -> 1 | M29: =IF((K29/I29)>1,1,K29/I29) -> 0.2645 | N29: 1500 | O29: 1500 | P29: =IF((O29/N29)>1,1,O29/N29) -> 1 | Q29: =IF((O29/I29)>1,1,O29/I29) -> 0.25 | R29: 1500 | S29: 0 | T29: =IF((S29/R29)>1,1,S29/R29) -> 0 | U29: =IF((S29/I29)>1,1,S29/I29) -> 0 | V29: 1500 | W29: 0 | X29: =IF((W29/V29)>1,1,W29/V29) -> 0 | Y29: =IF((W29/I29)>1,1,W29/I29) -> 0 | Z29: =+K29+O29+S29+W29 -> 3087 | AA29: =IF((Z29/I29)>1,1,Z29/I29) -> 0.5145
C30: 020409 Gestión para la construcción de la casa de la mujer | D30: 450203800 | E30: Casas de Igualdad de oportunidades para la mujer y el joven | F30: Número | G30: Incremento | H30: 0 | I30: 1 | J30: 0 | K30: 0 | M30: =IF((K30/I30)>1,1,K30/I30) -> 0 | N30: 0 | O30: 0.5 | Q30: =IF((O30/I30)>1,1,O30/I30) -> 0.5 | R30: 0 | S30: 0 | U30: =IF((S30/I30)>1,1,S30/I30) -> 0 | V30: 1 | W30: 0 | X30: =IF((W30/V30)>1,1,W30/V30) -> 0 | Y30: =IF((W30/I30)>1,1,W30/I30) -> 0 | Z30: =+K30+O30+S30+W30 -> 0.5 | AA30: =IF((Z30/I30)>1,1,Z30/I30) -> 0.5
C31: 020410 Atención a la comunidad LGTIBQ+. Como territorio protector y garante de derechos | D31: 450203800 | E31: Estrategias de promoción de la garantía de derechos implementadas | F31: Número | G31: Incremento | H31: 0 | I31: 1 | J31: 0.2 | K31: 0.1 | L31: =IF((K31/J31)>1,1,K31/J31) -> 0.5 | M31: =IF((K31/I31)>1,1,K31/I31) -> 0.1 | N31: 0.3 | O31: 0.1 | P31: =IF((O31/N31)>1,1,O31/N31) -> 0.33333333 | Q31: =IF((O31/I31)>1,1,O31/I31) -> 0.1 | R31: 0.3 | S31: 0 | T31: =IF((S31/R31)>1,1,S31/R31) -> 0 | U31: =IF((S31/I31)>1,1,S31/I31) -> 0 | V31: 0.2 | W31: 0 | X31: =IF((W31/V31)>1,1,W31/V31) -> 0 | Y31: =IF((W31/I31)>1,1,W31/I31) -> 0 | Z31: =+K31+O31+S31+W31 -> 0.2 | AA31: =IF((Z31/I31)>1,1,Z31/I31) -> 0.2
C32: 20411 Apoyo y fortalecimiento de los grupos étnicos en el municipio | D32: 450202201 | E32: Grupos étnicos asistidos técnicamente | F32: Número | G32: Incremento | H32: 0 | I32: 44 | J32: 11 | K32: 0 | L32: =IF((K32/J32)>1,1,K32/J32) -> 0 | M32: =IF((K32/I32)>1,1,K32/I32) -> 0 | N32: 11 | O32: 9 | P32: =IF((O32/N32)>1,1,O32/N32) -> 0.81818182 | Q32: =IF((O32/I32)>1,1,O32/I32) -> 0.20454545 | R32: 11 | S32: 0 | T32: =IF((S32/R32)>1,1,S32/R32) -> 0 | U32: =IF((S32/I32)>1,1,S32/I32) -> 0 | V32: 11 | W32: 0 | X32: =IF((W32/V32)>1,1,W32/V32) -> 0 | Y32: =IF((W32/I32)>1,1,W32/I32) -> 0 | Z32: =+K32+O32+S32+W32 -> 9 | AA32: =IF((Z32/I32)>1,1,Z32/I32) -> 0.20454545
C33: 20412 Mejoramiento de Infraestructura Juvenil | D33: 450202402 | E33: Casas de Igualdad de oportunidades para la mujer y el joven | F33: Número | G33: Incremento | H33: 0 | I33: 1 | J33: 0.25 | K33: 0 | L33: =IF((K33/J33)>1,1,K33/J33) -> 0 | M33: =IF((K33/I33)>1,1,K33/I33) -> 0 | N33: 0.25 | O33: 0.15 | P33: =IF((O33/N33)>1,1,O33/N33) -> 0.6 | Q33: =IF((O33/I33)>1,1,O33/I33) -> 0.15 | R33: 0.25 | S33: 0 | T33: =IF((S33/R33)>1,1,S33/R33) -> 0 | U33: =IF((S33/I33)>1,1,S33/I33) -> 0 | V33: 0.25 | W33: 0 | X33: =IF((W33/V33)>1,1,W33/V33) -> 0 | Y33: =IF((W33/I33)>1,1,W33/I33) -> 0 | Z33: =+K33+O33+S33+W33 -> 0.15 | AA33: =IF((Z33/I33)>1,1,Z33/I33) -> 0.15
K34: TOTAL 2024 | L34: =AVERAGE(L3:L33) -> 0.76425325 | M34: =AVERAGE(M3:M33) -> 0.31625932 | O34: TOTAL 2025 | P34: =AVERAGE(P3:P33) -> 0.93396029 | Q34: =AVERAGE(Q3:Q33) -> 0.36413192 | S34: TOTAL 2026 | T34: =AVERAGE(T3:T33) -> 0 | U34: =AVERAGE(U3:U33) -> 0 | W34: TOTAL 2026 | X34: =AVERAGE(X3:X33) -> 0 | Y34: =AVERAGE(Y3:Y33) -> 0 | Z34: TOTAL ACUMULADO | AA34: =AVERAGE(AA3:AA33) -> 0.54032963

Sheet SEC. TURISMO Y DLLO ECONOMICO
A1: AVANCE PLAN DE DESARROLLO JUNTOS CONSTRUIMOS 2024 -2027 03. JUNTOS POR EL TURISMO, EL EMPRENDIMIENTO, LA CONEXIÓN Y ALIANZAS PARA EL DESARROLLO
A2: COMPONENTE | B2: PROGRAMA | C2: CÓDIGO DE PRODUCTO | D2: INDICADOR DE PRODUCTO | E2: UNIDAD DE MEDIDA | F2: TENDENCIA | G2: LINEA BASE | H2: META CUATRENIO | I2: META 2024 | J2: AVANCE META 2024 | K2: % CUMPLIMIENTO P.A 2024 | L2: % AVANCE P.D. 2024 | M2: META 2025 | N2: AVANCE META 2025 | O2: % CUMPLIMIENTO P.A 2025 | P2: % AVANCE P.D. 2025 | Q2: META 2026 | R2: AVANCE META 2026 | S2: % CUMPLIMIENTO P.A 2026 | T2: % AVANCE P.D. 2026 | U2: META 2027 | V2: AVANCE META 2027 | W2: % CUMPLIMIENTO P.A 2026 | X2: % AVANCE P.D. 2026 | Y2: AVANCE ACUMULADO META 2024 Y 2025 | Z2: % AVANCE A LA FECHA P.D. | AA2: AVANCE PLAN DE DESARROLLO HASTA LA FECHA
A3: 0301 Juntos por el Turismo como eje del desarrollo municipal | B3: 30101 Implementación del Programa “De los zócalos al campo” | C3: 350209400 | D3: Documentos sobre medición y análisis de información turística realizados | E3: Número | F3: Incremento | G3: 0 | H3: 1 | I3: 0.25 | J3: 0.25 | K3: =IF((J3/I3)>1,1,J3/I3) -> 1 | L3: =IF((J3/H3)>1,1,J3/H3) -> 0.25 | M3: 0.25 | N3: 0 | O3: =IF((N3/M3)>1,1,N3/M3) -> 0 | P3: =IF((N3/H3)>1,1,N3/H3) -> 0 | Q3: 0.25 | R3: 0 | S3: =IF((R3/Q3)>1,1,R3/Q3) -> 0 | T3: =IF((R3/H3)>1,1,R3/H3) -> 0 | U3: 0.25 | V3: 0 | W3: =IF((V3/U3)>1,1,V3/U3) -> 0 | X3: =IF((V3/H3)>1,1,V3/H3) -> 0 | Y3: =+J3+N3+R3+V3 -> 0.25 | Z3: =IF((Y3/H3)>1,1,Y3/H3) -> 0.25 | AA3: LÍNEA ESTRATÉGICA | AB3: NUMERO DE PROGRAMAS | AC3: % AVANCE A LA FECHA P.D.
B4: 30102 Construcción y Mantenimiento de la infraestructura turística del municipio | C4: 350211300 | D4: Equipamientos contruidos | E4: Número | F4: Incremento | G4: 0 | H4: 2 | I4: 0 | J4: 0 | L4: =IF((J4/H4)>1,1,J4/H4) -> 0 | M4: 1 | N4: 1 | O4: =IF((N4/M4)>1,1,N4/M4) -> 1 | P4: =IF((N4/H4)>1,1,N4/H4) -> 0.5 | Q4: 1 | R4: 0 | S4: =IF((R4/Q4)>1,1,R4/Q4) -> 0 | T4: =IF((R4/H4)>1,1,R4/H4) -> 0 | U4: 0 | V4: 0 | X4: =IF((V4/H4)>1,1,V4/H4) -> 0 | Y4: =+J4+N4+R4+V4 -> 1 | Z4: =IF((Y4/H4)>1,1,Y4/H4) -> 0.5 | AA4: 03. JUNTOS POR EL TURISMO, EL EMPRENDIMIENTO, LA CONEXIÓN Y ALIANZAS PARA EL DESARROLLO | AB4: 7 | AC4: =Z10 -> 0.55214286
B5: 030103 Fortalecimiento de la Política Pública de Turismo | C5: 350200301 | D5: Planes gerenciales implementados en empresas ancladas a cadenas productivas | E5: Número | F5: Mantenimiento | G5: 1 | H5: 1 | I5: 1 | J5: 0.5 | K5: =IF((J5/I5)>1,1,J5/I5) -> 0.5 | L5: =IF((J5/H5)>1,1,J5/H5) -> 0.5 | M5: 1 | N5: 1 | O5: =IF((N5/M5)>1,1,N5/M5) -> 1 | P5: =IF((N5/H5)>1,1,N5/H5) -> 1 | Q5: 1 | R5: 0 | S5: =IF((R5/Q5)>1,1,R5/Q5) -> 0 | T5: =IF((R5/H5)>1,1,R5/H5) -> 0 | U5: 1 | V5: 0 | W5: =IF((V5/U5)>1,1,V5/U5) -> 0 | X5: =IF((V5/H5)>1,1,V5/H5) -> 0 | Y5: =+J5+N5+R5+V5 -> 1.5 | Z5: =IF((Y5/H5)>1,1,Y5/H5) -> 1
B6: 30104 Fortalecimiento de la promocion Turistica del territorio como eje Dinamizador de la economia | C6: 359906801 | D6: Planes estratégicos elaborados | E6: Número | F6: Incremento | G6: 0 | H6: 1 | I6: 0.25 | J6: 0.25 | K6: =IF((J6/I6)>1,1,J6/I6) -> 1 | L6: =IF((J6/H6)>1,1,J6/H6) -> 0.25 | M6: 0.25 | N6: 0 | O6: =IF((N6/M6)>1,1,N6/M6) -> 0 | P6: =IF((N6/H6)>1,1,N6/H6) -> 0 | Q6: 0.25 | R6: 0 | S6: =IF((R6/Q6)>1,1,R6/Q6) -> 0 | T6: =IF((R6/H6)>1,1,R6/H6) -> 0 | U6: 0.25 | V6: 0 | W6: =IF((V6/U6)>1,1,V6/U6) -> 0 | X6: =IF((V6/H6)>1,1,V6/H6) -> 0 | Y6: =+J6+N6+R6+V6 -> 0.25 | Z6: =IF((Y6/H6)>1,1,Y6/H6) -> 0.25
A7: 0302 Juntos por el Desarrollo económico, empresarial, innovación y TIC | B7: 030201 Fortalecimiento y dinamización de los sistemas de información digitales | C7: 230200300 | D7: Productos digitales desarrollados | E7: Número | F7: Incremento | G7: 0 | H7: 4 | I7: 1 | J7: 0.7 | K7: =IF((J7/I7)>1,1,J7/I7) -> 0.7 | L7: =IF((J7/H7)>1,1,J7/H7) -> 0.175 | M7: 1 | N7: 1 | O7: =IF((N7/M7)>1,1,N7/M7) -> 1 | P7: =IF((N7/H7)>1,1,N7/H7) -> 0.25 | Q7: 1 | R7: 0 | S7: =IF((R7/Q7)>1,1,R7/Q7) -> 0 | T7: =IF((R7/H7)>1,1,R7/H7) -> 0 | U7: 1 | V7: 0 | W7: =IF((V7/U7)>1,1,V7/U7) -> 0 | X7: =IF((V7/H7)>1,1,V7/H7) -> 0 | Y7: =+J7+N7+R7+V7 -> 1.7 | Z7: =IF((Y7/H7)>1,1,Y7/H7) -> 0.425
B8: 30202 Fortalecimiento de emprendedores y empresarios | C8: 350202000 | D8: Unidades productivas fortalecidas | E8: Número | F8: Incremento | G8: 0 | H8: 160 | I8: 40 | J8: 102 | K8: =IF((J8/I8)>1,1,J8/I8) -> 1 | L8: =IF((J8/H8)>1,1,J8/H8) -> 0.6375 | M8: 40 | N8: 22 | O8: =IF((N8/M8)>1,1,N8/M8) -> 0.55 | P8: =IF((N8/H8)>1,1,N8/H8) -> 0.1375 | Q8: 40 | R8: 0 | S8: =IF((R8/Q8)>1,1,R8/Q8) -> 0 | T8: =IF((R8/H8)>1,1,R8/H8) -> 0 | U8: 40 | V8: 0 | W8: =IF((V8/U8)>1,1,V8/U8) -> 0 | X8: =IF((V8/H8)>1,1,V8/H8) -> 0 | Y8: =+J8+N8+R8+V8 -> 124 | Z8: =IF((Y8/H8)>1,1,Y8/H8) -> 0.775
B9: 30203 Implementacion de conectividad en el Territorio. fortaleciendo el desarrollo equitativo de todos los sectores. | C9: 230102700 | D9: Conexiones a internet fijo y / o móvil | E9: Número | F9: Incremento | G9: 0 | H9: 200 | I9: 50 | J9: 0 | K9: =IF((J9/I9)>1,1,J9/I9) -> 0 | L9: =IF((J9/H9)>1,1,J9/H9) -> 0 | M9: 50 | N9: 133 | O9: =IF((N9/M9)>1,1,N9/M9) -> 1 | P9: =IF((N9/H9)>1,1,N9/H9) -> 0.665 | Q9: 50 | R9: 0 | S9: =IF((R9/Q9)>1,1,R9/Q9) -> 0 | T9: =IF((R9/H9)>1,1,R9/H9) -> 0 | U9: 50 | V9: 0 | W9: =IF((V9/U9)>1,1,V9/U9) -> 0 | X9: =IF((V9/H9)>1,1,V9/H9) -> 0 | Y9: =+J9+N9+R9+V9 -> 133 | Z9: =IF((Y9/H9)>1,1,Y9/H9) -> 0.665
J10: TOTAL 2024 | K10: =AVERAGE(K3:K9) -> 0.7 | L10: =AVERAGE(L3:L9) -> 0.25892857 | N10: TOTAL 2025 | O10: =AVERAGE(O3:O9) -> 0.65 | P10: =AVERAGE(P3:P9) -> 0.36464286 | R10: TOTAL 2026 | S10: =AVERAGE(S3:S9) -> 0 | T10: =AVERAGE(T3:T9) -> 0 | V10: TOTAL 2026 | W10: =AVERAGE(W3:W9) -> 0 | X10: =AVERAGE(X3:X9) -> 0 | Y10: TOTAL ACUMULADO | Z10: =AVERAGE(Z3:Z9) -> 0.55214286

Sheet SEC. PLANEACION Y OBRAS PUBLICA
A1: AVANCE PLAN DE DESARROLLO JUNTOS CLINEA ESTRATEGICA: 04. JUNTOS POR LA PLANEACIÓN Y DESARROLLO EQUITATIVO DEL TERRITORIO
A2: COMPONENTE | B2: PROGRAMA | C2: CÓDIGO DE PRODUCTO | D2: INDICADOR DE PRODUCTO | E2: UNIDAD DE MEDIDA | F2: TENDENCIA | G2: LINEA BASE | H2: META CUATRENIO | I2: META 2024 | J2: AVANCE META 2024 | K2: % CUMPLIMIENTO P.A 2024 | L2: % AVANCE P.D. 2024 | M2: META 2025 | N2: AVANCE META 2025 | O2: % CUMPLIMIENTO P.A 2025 | P2: % AVANCE P.D. 2025 | Q2: META 2026 | R2: AVANCE META 2026 | S2: % CUMPLIMIENTO P.A 2026 | T2: % AVANCE P.D. 2026 | U2: META 2027 | V2: AVANCE META 2027 | W2: % CUMPLIMIENTO P.A 2026 | X2: % AVANCE P.D. 2026 | Y2: AVANCE ACUMULADO META 2024 Y 2025 | Z2: % AVANCE A LA FECHA P.D. | AA2: AVANCE PLAN DE DESARROLLO HASTA LA FECHA
A3: 0401 Juntos por el Ordenamiento Territorial | B3: 040101 Formulación y ejecución de un plan estratégico de espacio público Municipal | C3: 400201601 | D3: Documentos de planeación en Ordenamiento Territorial implementados | E3: Número | F3: Incremento | G3: 0 | H3: 1 | I3: 0 | J3: 0 | L3: =IF((J3/H3)>1,1,J3/H3) -> 0 | M3: 1 | N3: 1 | O3: =IF((N3/M3)>1,1,N3/M3) -> 1 | P3: =IF((N3/H3)>1,1,N3/H3) -> 1 | Q3: 0 | R3: 0 | T3: =IF((R3/H3)>1,1,R3/H3) -> 0 | U3: 0 | V3: 0 | X3: =IF((V3/H3)>1,1,V3/H3) -> 0 | Y3: =+J3+N3+R3+V3 -> 1 | Z3: =IF((Y3/H3)>1,1,Y3/H3) -> 1 | AA3: LÍNEA ESTRATÉGICA | AB3: NUMERO DE PROGRAMAS | AC3: % AVANCE A LA FECHA P.D.
B4: 040102 Fortalecimiento a la Implementación del Esquema de Ordenamiento Territorial y sus directrices | C4: 450200110 | D4: Documentos de planeación en Ordenamiento Territorial implementados | E4: Número | F4: Incremento | G4: 0 | H4: 1 | I4: 0.25 | J4: 0 | K4: =IF((J4/I4)>1,1,J4/I4) -> 0 | L4: =IF((J4/H4)>1,1,J4/H4) -> 0 | M4: 0.25 | N4: 0.25 | O4: =IF((N4/M4)>1,1,N4/M4) -> 1 | P4: =IF((N4/H4)>1,1,N4/H4) -> 0.25 | Q4: 0.25 | R4: 0 | S4: =IF((R4/Q4)>1,1,R4/Q4) -> 0 | T4: =IF((R4/H4)>1,1,R4/H4) -> 0 | U4: 0.25 | V4: 0 | W4: =IF((V4/U4)>1,1,V4/U4) -> 0 | X4: =IF((V4/H4)>1,1,V4/H4) -> 0 | Y4: =+J4+N4+R4+V4 -> 0.25 | Z4: =IF((Y4/H4)>1,1,Y4/H4) -> 0.25 | AA4: 04. JUNTOS POR LA PLANEACIÓN Y DESARROLLO EQUITATIVO DEL TERRITORIO | AB4: 11 | AC4: =Z14 -> 0.42970265
B5: 040103 Fortalecimiento del consejo territorial de planeación y promover su participación en los principales escenarios de desarrollo | C5: 450200110 | D5: Instancias formales y no formales de participación fortalecidas | E5: Número | F5: Incremento | G5: 0 | H5: 1 | I5: 0.25 | J5: 0 | K5: =IF((J5/I5)>1,1,J5/I5) -> 0 | L5: =IF((J5/H5)>1,1,J5/H5) -> 0 | M5: 0.25 | N5: 0.25 | O5: =IF((N5/M5)>1,1,N5/M5) -> 1 | P5: =IF((N5/H5)>1,1,N5/H5) -> 0.25 | Q5: 0.25 | R5: 0 | S5: =IF((R5/Q5)>1,1,R5/Q5) -> 0 | T5: =IF((R5/H5)>1,1,R5/H5) -> 0 | U5: 0.25 | V5: 0 | W5: =IF((V5/U5)>1,1,V5/U5) -> 0 | X5: =IF((V5/H5)>1,1,V5/H5) -> 0 | Y5: =+J5+N5+R5+V5 -> 0.25 | Z5: =IF((Y5/H5)>1,1,Y5/H5) -> 0.25
A6: 0402 Juntos por el Equipamiento Público | B6: 040201 Aumento de los espacios de infraestructura física de integración y encuentro para la comunidad guatapense | C6: 409901101 | D6: Areas Físicas Adecuadas | E6: Metros cuadrados | F6: Incremento | G6: 0 | H6: 2000 | I6: 500 | J6: 10 | K6: =IF((J6/I6)>1,1,J6/I6) -> 0.02 | L6: =IF((J6/H6)>1,1,J6/H6) -> 0.005 | M6: 500 | N6: 350 | O6: =IF((N6/M6)>1,1,N6/M6) -> 0.7 | P6: =IF((N6/H6)>1,1,N6/H6) -> 0.175 | Q6: 500 | R6: 0 | S6: =IF((R6/Q6)>1,1,R6/Q6) -> 0 | T6: =IF((R6/H6)>1,1,R6/H6) -> 0 | U6: 500 | V6: 0 | W6: =IF((V6/U6)>1,1,V6/U6) -> 0 | X6: =IF((V6/H6)>1,1,V6/H6) -> 0 | Y6: =+J6+N6+R6+V6 -> 360 | Z6: =IF((Y6/H6)>1,1,Y6/H6) -> 0.18
B7: 040202 Ampliación del programa de zocalización de Guatapé | C7: 409901101 | D7: Areas Fisicas Adecuadas | E7: Metros cuadrados | F7: Incremento | G7: 0 | H7: 200 | I7: 50 | J7: 0 | K7: =IF((J7/I7)>1,1,J7/I7) -> 0 | L7: =IF((J7/H7)>1,1,J7/H7) -> 0 | M7: 50 | N7: 200 | O7: =IF((N7/M7)>1,1,N7/M7) -> 1 | P7: =IF((N7/H7)>1,1,N7/H7) -> 1 | Q7: 50 | R7: 0 | S7: =IF((R7/Q7)>1,1,R7/Q7) -> 0 | T7: =IF((R7/H7)>1,1,R7/H7) -> 0 | U7: 50 | V7: 0 | W7: =IF((V7/U7)>1,1,V7/U7) -> 0 | X7: =IF((V7/H7)>1,1,V7/H7) -> 0 | Y7: =+J7+N7+R7+V7 -> 200 | Z7: =IF((Y7/H7)>1,1,Y7/H7) -> 1
B8: 040203 Expansión del servicio de alumbrado público | C8: 210201000 | D8: Redes de alumbrado público ampliadas | E8: Metros | F8: Incremento | G8: 0 | H8: 1000 | I8: 250 | J8: 50 | K8: =IF((J8/I8)>1,1,J8/I8) -> 0.2 | L8: =IF((J8/H8)>1,1,J8/H8) -> 0.05 | M8: 250 | N8: 5863 | O8: =IF((N8/M8)>1,1,N8/M8) -> 1 | P8: =IF((N8/H8)>1,1,N8/H8) -> 1 | Q8: 250 | R8: 0 | S8: =IF((R8/Q8)>1,1,R8/Q8) -> 0 | T8: =IF((R8/H8)>1,1,R8/H8) -> 0 | U8: 250 | V8: 0 | W8: =IF((V8/U8)>1,1,V8/U8) -> 0 | X8: =IF((V8/H8)>1,1,V8/H8) -> 0 | Y8: =+J8+N8+R8+V8 -> 5913 | Z8: =IF((Y8/H8)>1,1,Y8/H8) -> 1
B9: 040204 Construcción de Infraestructura para la promoción de métodos alternativos de transporte saludables en sectores estratégicos del municipio | C9: 240212100 | D9: Andén construido | E9: Metros | F9: Incremento | G9: 0 | H9: 1600 | I9: 400 | J9: 0 | K9: =IF((J9/I9)>1,1,J9/I9) -> 0 | L9: =IF((J9/H9)>1,1,J9/H9) -> 0 | M9: 400 | N9: 0.1 | O9: =IF((N9/M9)>1,1,N9/M9) -> 0.00025 | P9: =IF((N9/H9)>1,1,N9/H9) -> 6.25e-05 | Q9: 400 | R9: 0 | S9: =IF((R9/Q9)>1,1,R9/Q9) -> 0 | T9: =IF((R9/H9)>1,1,R9/H9) -> 0 | U9: 400 | V9: 0 | W9: =IF((V9/U9)>1,1,V9/U9) -> 0 | X9: =IF((V9/H9)>1,1,V9/H9) -> 0 | Y9: =+J9+N9+R9+V9 -> 0.1 | Z9: =IF((Y9/H9)>1,1,Y9/H9) -> 6.25e-05
A10: 0403 Juntos por la Dignificación de la Vivienda | B10: 40301 Otorgamiento de Subsidios para la adquisición de VIS (vivienda de interés social) y/o VIP (Vivienda de Interés Prioritario) | C10: 400103100 | D10: Hogares beneficiados con adquisición de vivienda | E10: Número | F10: Incremento | G10: 0 | H10: 150 | I10: 50 | J10: 0 | K10: =IF((J10/I10)>1,1,J10/I10) -> 0 | L10: =IF((J10/H10)>1,1,J10/H10) -> 0 | M10: 0 | N10: 88 | P10: =IF((N10/H10)>1,1,N10/H10) -> 0.58666667 | Q10: 0 | R10: 0 | T10: =IF((R10/H10)>1,1,R10/H10) -> 0 | U10: 100 | V10: 0 | W10: =IF((V10/U10)>1,1,V10/U10) -> 0 | X10: =IF((V10/H10)>1,1,V10/H10) -> 0 | Y10: =+J10+N10+R10+V10 -> 88 | Z10: =IF((Y10/H10)>1,1,Y10/H10) -> 0.58666667
B11: 040302 Otorgamiento de Subsidios para el mejoramiento de vivienda. garantizando hogares guatapenses dignos | C11: 400103200 | D11: Hogares beneficiados con mejoramiento de una vivienda | E11: Número | F11: Incremento | G11: 0 | H11: 150 | I11: 10 | J11: 0 | K11: =IF((J11/I11)>1,1,J11/I11) -> 0 | L11: =IF((J11/H11)>1,1,J11/H11) -> 0 | M11: 40 | N11: 69 | O11: =IF((N11/M11)>1,1,N11/M11) -> 1 | P11: =IF((N11/H11)>1,1,N11/H11) -> 0.46 | Q11: 40 | R11: 0 | S11: =IF((R11/Q11)>1,1,R11/Q11) -> 0 | T11: =IF((R11/H11)>1,1,R11/H11) -> 0 | U11: 60 | V11: 0 | W11: =IF((V11/U11)>1,1,V11/U11) -> 0 | X11: =IF((V11/H11)>1,1,V11/H11) -> 0 | Y11: =+J11+N11+R11+V11 -> 69 | Z11: =IF((Y11/H11)>1,1,Y11/H11) -> 0.46
B12: 040303 Otorgamiento de Subsidios para reubicación de viviendas asentadas en zonas de alto riesgo | C12: 400103100 | D12: Hogares beneficiados con adquisición de vivienda | E12: Número | F12: Incremento | G12: 0 | H12: 4 | I12: 1 | J12: 0 | K12: =IF((J12/I12)>1,1,J12/I12) -> 0 | L12: =IF((J12/H12)>1,1,J12/H12) -> 0 | M12: 1 | N12: 0 | O12: =IF((N12/M12)>1,1,N12/M12) -> 0 | P12: =IF((N12/H12)>1,1,N12/H12) -> 0 | Q12: 1 | R12: 0 | S12: =IF((R12/Q12)>1,1,R12/Q12) -> 0 | T12: =IF((R12/H12)>1,1,R12/H12) -> 0 | U12: 1 | V12: 0 | W12: =IF((V12/U12)>1,1,V12/U12) -> 0 | X12: =IF((V12/H12)>1,1,V12/H12) -> 0 | Y12: =+J12+N12+R12+V12 -> 0 | Z12: =IF((Y12/H12)>1,1,Y12/H12) -> 0
B13: 040304 Gestión de la titulación y legalización de predios construidos en el municipio | C13: 400300800 | D13: Asistencias técnicas y jurídicas realizadas | E13: Número | F13: Incremento | G13: 0 | H13: 33 | I13: 4 | J13: 0 | K13: =IF((J13/I13)>1,1,J13/I13) -> 0 | L13: =IF((J13/H13)>1,1,J13/H13) -> 0 | M13: 9 | N13: 0 | O13: =IF((N13/M13)>1,1,N13/M13) -> 0 | P13: =IF((N13/H13)>1,1,N13/H13) -> 0 | Q13: 13 | R13: 0 | S13: =IF((R13/Q13)>1,1,R13/Q13) -> 0 | T13: =IF((R13/H13)>1,1,R13/H13) -> 0 | U13: 7 | V13: 0 | W13: =IF((V13/U13)>1,1,V13/U13) -> 0 | X13: =IF((V13/H13)>1,1,V13/H13) -> 0 | Y13: =+J13+N13+R13+V13 -> 0 | Z13: =IF((Y13/H13)>1,1,Y13/H13) -> 0
J14: TOTAL 2024 | K14: =AVERAGE(K3:K13) -> 0.022 | L14: =AVERAGE(L3:L13) -> 0.005 | N14: TOTAL 2025 | O14: =AVERAGE(O3:O13) -> 0.670025 | P14: =AVERAGE(P3:P13) -> 0.42924811 | R14: TOTAL 2026 | S14: =AVERAGE(S3:S13) -> 0 | T14: =AVERAGE(T3:T13) -> 0 | V14: TOTAL 2026 | W14: =AVERAGE(W3:W13) -> 0 | X14: =AVERAGE(X3:X13) -> 0 | Y14: TOTAL ACUMULADO | Z14: =AVERAGE(Z3:Z13) -> 0.42970265

Sheet SEC. MEDIO AMBIENTE Y DLLO RURA
A1: AVANCE PLAN DE DESARROLLO JUNTOS CLINEA ESTRATEGICA: 05. JUNTOS POR EL MEDIO AMBIENTE, LA PREVENCIÓN Y ATENCIÓN DE EMERGENCIAS Y DESASTRES Y LA DIGNIFICACIÓN DEL CAMPO GUATAPENSE
A2: COMPONENTE | B2: PROGRAMA | C2: CÓDIGO DE PRODUCTO | D2: INDICADOR DE PRODUCTO | E2: UNIDAD DE MEDIDA | F2: TENDENCIA | G2: LINEA BASE | H2: META CUATRENIO | I2: META 2024 | J2: AVANCE META 2024 | K2: % CUMPLIMIENTO P.A 2024 | L2: % AVANCE P.D. 2024 | M2: META 2025 | N2: AVANCE META 2025 | O2: % CUMPLIMIENTO P.A 2025 | P2: % AVANCE P.D. 2025 | Q2: META 2026 | R2: AVANCE META 2026 | S2: % CUMPLIMIENTO P.A 2026 | T2: % AVANCE P.D. 2026 | U2: META 2027 | V2: AVANCE META 2027 | W2: % CUMPLIMIENTO P.A 2026 | X2: % AVANCE P.D. 2026 | Y2: AVANCE ACUMULADO META 2024 Y 2025 | Z2: % AVANCE A LA FECHA P.D. | AA2: AVANCE PLAN DE DESARROLLO HASTA LA FECHA
A3: 0501 Juntos por la Prestación de Servicios Públicos de calidad | B3: 050101 Ampliación y reposición de la infraestructura para la prestación de los servicios públicos domiciliarios de acueducto y alcantarillado | C3: 400300800 | D3: Proyectos de acueducto, alcantarillado y aseo apoyados financieramente | E3: Número | F3: Incremento | G3: 0 | H3: 2 | I3: 0.5 | J3: 0.5 | K3: =IF((J3/I3)>1,1,J3/I3) -> 1 | L3: =IF((J3/H3)>1,1,J3/H3) -> 0.25 | M3: 0.5 | N3: 1.5 | O3: =IF((N3/M3)>1,1,N3/M3) -> 1 | P3: =IF((N3/H3)>1,1,N3/H3) -> 0.75 | Q3: 0.5 | R3: 0 | S3: =IF((R3/Q3)>1,1,R3/Q3) -> 0 | T3: =IF((R3/H3)>1,1,R3/H3) -> 0 | U3: 0.5 | V3: 0 | W3: =IF((V3/U3)>1,1,V3/U3) -> 0 | X3: =IF((V3/H3)>1,1,V3/H3) -> 0 | Y3: =+J3+N3+R3+V3 -> 2 | Z3: =IF((Y3/H3)>1,1,Y3/H3) -> 1 | AA3: LÍNEA ESTRATÉGICA | AB3: NUMERO DE PROGRAMAS | AC3: % AVANCE A LA FECHA P.D.
B4: 050102 Ampliación de la cobertura. el abastecimiento y la calidad en el servicio de acueducto y alcantarillado para el municipio de Guatapé | C4: 400300800 | D4: Proyectos de acueducto, alcantarillado y aseo apoyados financieramente | E4: Número | F4: Incremento | G4: 0 | H4: 1 | I4: 0 | J4: 1 | L4: =IF((J4/H4)>1,1,J4/H4) -> 1 | M4: 0 | N4: 2 | P4: =IF((N4/H4)>1,1,N4/H4) -> 1 | Q4: 0 | R4: 0 | T4: =IF((R4/H4)>1,1,R4/H4) -> 0 | U4: 1 | V4: 0 | W4: =IF((V4/U4)>1,1,V4/U4) -> 0 | X4: =IF((V4/H4)>1,1,V4/H4) -> 0 | Y4: =+J4+N4+R4+V4 -> 3 | Z4: =IF((Y4/H4)>1,1,Y4/H4) -> 1 | AA4: 05. JUNTOS POR EL MEDIO AMBIENTE, LA PREVENCIÓN Y ATENCIÓN DE EMERGENCIAS Y DESASTRES Y LA DIGNIFICACIÓN DEL CAMPO GUATAPENSE | AB4: 19 | AC4: =Z22 -> 0.64163234
B5: 50103 Gestión para la adquisición de predios de protección hídrica para la protección de cuencas abastecedoras de acueductos para la prestación del servicio de acueducto urbano y rural | C5: 320305000 | D5: Áreas protegidas | E5: Hectáreas | F5: Incremento | G5: 0 | H5: 4 | I5: 0 | J5: 0 | L5: =IF((J5/H5)>1,1,J5/H5) -> 0 | M5: 2 | N5: 0 | O5: =IF((N5/M5)>1,1,N5/M5) -> 0 | P5: =IF((N5/H5)>1,1,N5/H5) -> 0 | Q5: 2 | R5: 0 | S5: =IF((R5/Q5)>1,1,R5/Q5) -> 0 | T5: =IF((R5/H5)>1,1,R5/H5) -> 0 | U5: 0 | V5: 0 | X5: =IF((V5/H5)>1,1,V5/H5) -> 0 | Y5: =+J5+N5+R5+V5 -> 0 | Z5: =IF((Y5/H5)>1,1,Y5/H5) -> 0
B6: 050104 Optimización y ampliación del relleno sanitario municipal para aumentar su vida útil | C6: 400301200 | D6: Soluciones de disposición final de residuos solidos construidas | E6: Número | F6: Incremento | G6: 0 | H6: 1 | I6: 0.25 | J6: 0 | K6: =IF((J6/I6)>1,1,J6/I6) -> 0 | L6: =IF((J6/H6)>1,1,J6/H6) -> 0 | M6: 0.25 | N6: 0.1 | O6: =IF((N6/M6)>1,1,N6/M6) -> 0.4 | P6: =IF((N6/H6)>1,1,N6/H6) -> 0.1 | Q6: 0.25 | R6: 0 | S6: =IF((R6/Q6)>1,1,R6/Q6) -> 0 | T6: =IF((R6/H6)>1,1,R6/H6) -> 0 | U6: 0.25 | V6: 0 | W6: =IF((V6/U6)>1,1,V6/U6) -> 0 | X6: =IF((V6/H6)>1,1,V6/H6) -> 0 | Y6: =+J6+N6+R6+V6 -> 0.1 | Z6: =IF((Y6/H6)>1,1,Y6/H6) -> 0.1
B7: 050105 Optimización y ampliación de la Planta de Compostaje para tratamiento de los residuos orgánicos | C7: 400301200 | D7: Soluciones de disposición final de residuos solidos construidas | E7: Número | F7: Incremento | G7: 0 | H7: 1 | I7: 0.25 | J7: 0.25 | K7: =IF((J7/I7)>1,1,J7/I7) -> 1 | L7: =IF((J7/H7)>1,1,J7/H7) -> 0.25 | M7: 0.25 | N7: 0.25 | O7: =IF((N7/M7)>1,1,N7/M7) -> 1 | P7: =IF((N7/H7)>1,1,N7/H7) -> 0.25 | Q7: 0.25 | R7: 0 | S7: =IF((R7/Q7)>1,1,R7/Q7) -> 0 | T7: =IF((R7/H7)>1,1,R7/H7) -> 0 | U7: 0.25 | V7: 0 | W7: =IF((V7/U7)>1,1,V7/U7) -> 0 | X7: =IF((V7/H7)>1,1,V7/H7) -> 0 | Y7: =+J7+N7+R7+V7 -> 0.5 | Z7: =IF((Y7/H7)>1,1,Y7/H7) -> 0.5
B8: 050106 Fortalecimiento y acompañamiento integral a los prestadores de empresas prestadoras de servicios públicos del Municipio | C8: 400305201 | D8: Personas prestadoras asistidas técnicamente | E8: Número | F8: Mantenimiento | G8: 6 | H8: 6 | I8: 6 | J8: 6 | K8: =IF((J8/I8)>1,1,J8/I8) -> 1 | L8: =IF((J8/H8)>1,1,J8/H8) -> 1 | M8: 6 | N8: 6 | O8: =IF((N8/M8)>1,1,N8/M8) -> 1 | P8: =IF((N8/H8)>1,1,N8/H8) -> 1 | Q8: 6 | R8: 0 | S8: =IF((R8/Q8)>1,1,R8/Q8) -> 0 | T8: =IF((R8/H8)>1,1,R8/H8) -> 0 | U8: 6 | V8: 0 | W8: =IF((V8/U8)>1,1,V8/U8) -> 0 | X8: =IF((V8/H8)>1,1,V8/H8) -> 0 | Y8: =+N8 -> 6 | Z8: =IF((Y8/H8)>1,1,Y8/H8) -> 1
B9: 50107 Gestión para la construcción de la planta de tratamiento y potabilización de agua de la vereda quebrada arriba | C9: 400301503 | D9: Plantas de tratamiento de agua potable construidas | E9: Número | F9: Incremento | G9: 0 | H9: 1 | I9: 0 | J9: 0 | L9: =IF((J9/H9)>1,1,J9/H9) -> 0 | M9: 0 | N9: 0.1 | Q9: 0.5 | R9: 0 | S9: =IF((R9/Q9)>1,1,R9/Q9) -> 0 | T9: =IF((R9/H9)>1,1,R9/H9) -> 0 | U9: 0.5 | V9: 0 | W9: =IF((V9/U9)>1,1,V9/U9) -> 0 | X9: =IF((V9/H9)>1,1,V9/H9) -> 0 | Y9: =+J9+N9+R9+V9 -> 0.1 | Z9: =IF((Y9/H9)>1,1,Y9/H9) -> 0.1
